Workbook

Sheet EXPOSURE
A1: BU | B1: Fund | C1: Company | D1: Market Value (USD) | E1: BICS CODE | F1: SECTOR CODE | G1: INDUSTRY GROUP CODE | H1: INDUSTRY CODE | I1: SUB INDUSTRY CODE | J1: SECTOR NAME | K1: INDUSTRY GROUP NAME | L1: INDUSTRY NAME | M1: SUB INDUSTRY NAME
A2: Credit | B2: ALTURAS II | C2: AEROMEXICO | D2: 18854900 | E2: 1711121010 | F2: 17 | G2: 1711 | H2: 171112 | I2: 17111210 | J2: =+IFERROR(VLOOKUP(F2,BD_GICS!A:B,2,0),"") -> Industrials | K2: =+IFERROR(VLOOKUP(G2,BD_GICS!C:D,2,0),"") -> Industrial Services | L2: =+IFERROR(VLOOKUP(H2,BD_GICS!E:F,2,0),"") -> Transportation & Logistics | M2: =+IFERROR(VLOOKUP(I2,BD_GICS!G:H,2,0),"") -> Airlines
A3: Credit | B3: ALTURAS II | C3: AEROPUERTO INTERNACIONAL DE QUITO | D3: 7912206.8 | E3: 3712 | F3: 37 | G3: 3712 | H3: 3712 | I3: 3712 | J3: =+IFERROR(VLOOKUP(F3,BD_GICS!A:B,2,0),"") -> Industrials | K3: =+IFERROR(VLOOKUP(G3,BD_GICS!C:D,2,0),"") -> Transportation & Logistics | L3: =+IFERROR(VLOOKUP(H3,BD_GICS!E:F,2,0),"") | M3: =+IFERROR(VLOOKUP(I3,BD_GICS!G:H,2,0),"")
A4: Credit | B4: ALTURAS II | C4: ALBANESI | D4: 8656216.5 | E4: 2010101110 | F4: 20 | G4: 2010 | H4: 201010 | I4: 20101011 | J4: =+IFERROR(VLOOKUP(F4,BD_GICS!A:B,2,0),"") -> Utilities | K4: =+IFERROR(VLOOKUP(G4,BD_GICS!C:D,2,0),"") -> Utilities | L4: =+IFERROR(VLOOKUP(H4,BD_GICS!E:F,2,0),"") -> Electric Utilities | M4: =+IFERROR(VLOOKUP(I4,BD_GICS!G:H,2,0),"") -> Power Generation
A5: Credit | B5: ALTURAS II | C5: ALTO MAIPO | D5: 8533429.7 | E5: 3411 | F5: 34 | G5: 3411 | H5: 3411 | I5: 3411 | J5: =+IFERROR(VLOOKUP(F5,BD_GICS!A:B,2,0),"") -> Energy | K5: =+IFERROR(VLOOKUP(G5,BD_GICS!C:D,2,0),"") -> Renewable Energy | L5: =+IFERROR(VLOOKUP(H5,BD_GICS!E:F,2,0),"") | M5: =+IFERROR(VLOOKUP(I5,BD_GICS!G:H,2,0),"")
A6: Credit | B6: ALTURAS II | C6: AUTOPISTAS DEL ATLANTICO | D6: 3516524.7 | E6: 1711131112 | F6: 17 | G6: 1711 | H6: 171113 | I6: 17111311 | J6: =+IFERROR(VLOOKUP(F6,BD_GICS!A:B,2,0),"") -> Industrials | K6: =+IFERROR(VLOOKUP(G6,BD_GICS!C:D,2,0),"") -> Industrial Services | L6: =+IFERROR(VLOOKUP(H6,BD_GICS!E:F,2,0),"") -> Engineering & Construction | M6: =+IFERROR(VLOOKUP(I6,BD_GICS!G:H,2,0),"") -> Infrastructure Construction
A7: Credit | B7: ALTURAS II | C7: CONSTELLATION | D7: 31583031 | E7: 3413 | F7: 34 | G7: 3413 | H7: 3413 | I7: 3413 | J7: =+IFERROR(VLOOKUP(F7,BD_GICS!A:B,2,0),"") -> Energy | K7: =+IFERROR(VLOOKUP(G7,BD_GICS!C:D,2,0),"") -> Oil & Gas Services & Equipment | L7: =+IFERROR(VLOOKUP(H7,BD_GICS!E:F,2,0),"") | M7: =+IFERROR(VLOOKUP(I7,BD_GICS!G:H,2,0),"")
A8: Credit | B8: ALTURAS II | C8: LATINA OFFSHORE | D8: 22708395 | E8: 13101110 | F8: 13 | G8: 1310 | H8: 131011 | I8: 13101110 | J8: =+IFERROR(VLOOKUP(F8,BD_GICS!A:B,2,0),"") -> Energy | K8: =+IFERROR(VLOOKUP(G8,BD_GICS!C:D,2,0),"") -> Oil & Gas | L8: =+IFERROR(VLOOKUP(H8,BD_GICS!E:F,2,0),"") -> Oil & Gas Services & Equip | M8: =+IFERROR(VLOOKUP(I8,BD_GICS!G:H,2,0),"") -> Drilling & Drilling Support
A9: Credit | B9: ALTURAS II | C9: MSU ENERGY | D9: 2810091.3 | E9: 3911 | F9: 39 | G9: 3911 | H9: 3911 | I9: 3911 | J9: =+IFERROR(VLOOKUP(F9,BD_GICS!A:B,2,0),"") -> Utilities | K9: =+IFERROR(VLOOKUP(G9,BD_GICS!C:D,2,0),"") -> Power Generation | L9: =+IFERROR(VLOOKUP(H9,BD_GICS!E:F,2,0),"") | M9: =+IFERROR(VLOOKUP(I9,BD_GICS!G:H,2,0),"")
A10: Equity | B10: GLORY | C10: 3R PETROLEUM OLEO E GAS | D10: 5941498.9 | E10: 1310101110 | F10: 13 | G10: 1310 | H10: 131010 | I10: 13101011 | J10: =+IFERROR(VLOOKUP(F10,BD_GICS!A:B,2,0),"") -> Energy | K10: =+IFERROR(VLOOKUP(G10,BD_GICS!C:D,2,0),"") -> Oil & Gas | L10: =+IFERROR(VLOOKUP(H10,BD_GICS!E:F,2,0),"") -> Oil & Gas Producers | M10: =+IFERROR(VLOOKUP(I10,BD_GICS!G:H,2,0),"") -> Exploration & Production
A11: Equity | B11: GLORY | C11: AGUAS ANDINAS | D11: 1004211.1 | E11: 2010 | F11: 20 | G11: 2010 | H11: 2010 | I11: 2010 | J11: =+IFERROR(VLOOKUP(F11,BD_GICS!A:B,2,0),"") -> Utilities | K11: =+IFERROR(VLOOKUP(G11,BD_GICS!C:D,2,0),"") -> Utilities | L11: =+IFERROR(VLOOKUP(H11,BD_GICS!E:F,2,0),"") | M11: =+IFERROR(VLOOKUP(I11,BD_GICS!G:H,2,0),"")
A12: Equity | B12: GLORY | C12: AMBEV | D12: 3824532.9 | E12: 1210111010 | F12: 12 | G12: 1210 | H12: 121011 | I12: 12101110 | J12: =+IFERROR(VLOOKUP(F12,BD_GICS!A:B,2,0),"") -> Consumer Staples | K12: =+IFERROR(VLOOKUP(G12,BD_GICS!C:D,2,0),"") -> Consumer Staple Products | L12: =+IFERROR(VLOOKUP(H12,BD_GICS!E:F,2,0),"") -> Beverages | M12: =+IFERROR(VLOOKUP(I12,BD_GICS!G:H,2,0),"") -> Alcoholic Beverages
A13: Equity | B13: GLORY | C13: AMERICA MOVIL | D13: 3603756.9 | E13: 1011 | F13: 10 | G13: 1011 | H13: 1011 | I13: 1011 | J13: =+IFERROR(VLOOKUP(F13,BD_GICS!A:B,2,0),"") -> Communications | K13: =+IFERROR(VLOOKUP(G13,BD_GICS!C:D,2,0),"") -> Telecommunications | L13: =+IFERROR(VLOOKUP(H13,BD_GICS!E:F,2,0),"") | M13: =+IFERROR(VLOOKUP(I13,BD_GICS!G:H,2,0),"")
... A81: Equity | B81: GLORY | C81: WAL-MART MEXICO | D81: 4917073 | E81: 1211 | F81: 12 | G81: 1211 | H81: 1211 | I81: 1211 | J81: =+IFERROR(VLOOKUP(F81,BD_GICS!A:B,2,0),"") -> Consumer Staples | K81: =+IFERROR(VLOOKUP(G81,BD_GICS!C:D,2,0),"") -> Retail & Wholesale - Staples | L81: =+IFERROR(VLOOKUP(H81,BD_GICS!E:F,2,0),"") | M81: =+IFERROR(VLOOKUP(I81,BD_GICS!G:H,2,0),"")
A82: Credit | B82: MCCDF | C82: 522 FUNDING CLO | D82: 2476868 | E82: CLO | J82: =+IFERROR(VLOOKUP(F82,BD_GICS!A:B,2,0),"") | K82: =+IFERROR(VLOOKUP(G82,BD_GICS!C:D,2,0),"") | L82: =+IFERROR(VLOOKUP(H82,BD_GICS!E:F,2,0),"") | M82: =+IFERROR(VLOOKUP(I82,BD_GICS!G:H,2,0),"")
A83: Credit | B83: MCCDF | C83: ALLEGANY PARK CLO | D83: 1362329.4 | E83: CLO | J83: =+IFERROR(VLOOKUP(F83,BD_GICS!A:B,2,0),"") | K83: =+IFERROR(VLOOKUP(G83,BD_GICS!C:D,2,0),"") | L83: =+IFERROR(VLOOKUP(H83,BD_GICS!E:F,2,0),"") | M83: =+IFERROR(VLOOKUP(I83,BD_GICS!G:H,2,0),"")
A84: Credit | B84: MCCDF | C84: APIDOS CLO LTD | D84: 1053553.7 | E84: CLO | J84: =+IFERROR(VLOOKUP(F84,BD_GICS!A:B,2,0),"") | K84: =+IFERROR(VLOOKUP(G84,BD_GICS!C:D,2,0),"") | L84: =+IFERROR(VLOOKUP(H84,BD_GICS!E:F,2,0),"") | M84: =+IFERROR(VLOOKUP(I84,BD_GICS!G:H,2,0),"")
A85: Credit | B85: MCCDF | C85: ARBOUR CLO | D85: 2098636.2 | E85: CLO | J85: =+IFERROR(VLOOKUP(F85,BD_GICS!A:B,2,0),"") | K85: =+IFERROR(VLOOKUP(G85,BD_GICS!C:D,2,0),"") | L85: =+IFERROR(VLOOKUP(H85,BD_GICS!E:F,2,0),"") | M85: =+IFERROR(VLOOKUP(I85,BD_GICS!G:H,2,0),"")
A86: Credit | B86: MCCDF | C86: ARES CLO LTD | D86: 6109108.9 | E86: CLO | J86: =+IFERROR(VLOOKUP(F86,BD_GICS!A:B,2,0),"") | K86: =+IFERROR(VLOOKUP(G86,BD_GICS!C:D,2,0),"") | L86: =+IFERROR(VLOOKUP(H86,BD_GICS!E:F,2,0),"") | M86: =+IFERROR(VLOOKUP(I86,BD_GICS!G:H,2,0),"")
A87: Credit | B87: MCCDF | C87: BABSON CLO LTD | D87: 923139.63 | E87: CLO | J87: =+IFERROR(VLOOKUP(F87,BD_GICS!A:B,2,0),"") | K87: =+IFERROR(VLOOKUP(G87,BD_GICS!C:D,2,0),"") | L87: =+IFERROR(VLOOKUP(H87,BD_GICS!E:F,2,0),"") | M87: =+IFERROR(VLOOKUP(I87,BD_GICS!G:H,2,0),"")
A88: Credit | B88: MCCDF | C88: BAIN CAPITAL CREDIT CLO | D88: 1609238.2 | E88: CLO | J88: =+IFERROR(VLOOKUP(F88,BD_GICS!A:B,2,0),"") | K88: =+IFERROR(VLOOKUP(G88,BD_GICS!C:D,2,0),"") | L88: =+IFERROR(VLOOKUP(H88,BD_GICS!E:F,2,0),"") | M88: =+IFERROR(VLOOKUP(I88,BD_GICS!G:H,2,0),"")
A89: Credit | B89: MCCDF | C89: BEECHWOOD PARK CLO LTD | D89: 1879569.7 | E89: CLO | J89: =+IFERROR(VLOOKUP(F89,BD_GICS!A:B,2,0),"") | K89: =+IFERROR(VLOOKUP(G89,BD_GICS!C:D,2,0),"") | L89: =+IFERROR(VLOOKUP(H89,BD_GICS!E:F,2,0),"") | M89: =+IFERROR(VLOOKUP(I89,BD_GICS!G:H,2,0),"")
A90: Credit | B90: MCCDF | C90: CARLYLE GLOBAL MARKET | D90: 4009689.9 | E90: FUND | J90: =+IFERROR(VLOOKUP(F90,BD_GICS!A:B,2,0),"") | K90: =+IFERROR(VLOOKUP(G90,BD_GICS!C:D,2,0),"") | L90: =+IFERROR(VLOOKUP(H90,BD_GICS!E:F,2,0),"") | M90: =+IFERROR(VLOOKUP(I90,BD_GICS!G:H,2,0),"")
A91: Credit | B91: MCCDF | C91: CIFC EUROPEAN FUNDING CLO | D91: 2676416.9 | E91: CLO | J91: =+IFERROR(VLOOKUP(F91,BD_GICS!A:B,2,0),"") | K91: =+IFERROR(VLOOKUP(G91,BD_GICS!C:D,2,0),"") | L91: =+IFERROR(VLOOKUP(H91,BD_GICS!E:F,2,0),"") | M91: =+IFERROR(VLOOKUP(I91,BD_GICS!G:H,2,0),"")
A92: Credit | B92: MCCDF | C92: CORDATUS CLO PLC | D92: 6172086.4 | E92: CLO | J92: =+IFERROR(VLOOKUP(F92,BD_GICS!A:B,2,0),"") | K92: =+IFERROR(VLOOKUP(G92,BD_GICS!C:D,2,0),"") | L92: =+IFERROR(VLOOKUP(H92,BD_GICS!E:F,2,0),"") | M92: =+IFERROR(VLOOKUP(I92,BD_GICS!G:H,2,0),"")
A93: Credit | B93: MCCDF | C93: INVESCO CLO 2021-1 | D93: 2832682.2 | E93: CLO | J93: =+IFERROR(VLOOKUP(F93,BD_GICS!A:B,2,0),"") | K93: =+IFERROR(VLOOKUP(G93,BD_GICS!C:D,2,0),"") | L93: =+IFERROR(VLOOKUP(H93,BD_GICS!E:F,2,0),"") | M93: =+IFERROR(VLOOKUP(I93,BD_GICS!G:H,2,0),"")
... A100: Credit | B100: MCCDF | C100: PENTA CLO SA | D100: 4306143.7 | E100: CLO | J100: =+IFERROR(VLOOKUP(F100,BD_GICS!A:B,2,0),"") | K100: =+IFERROR(VLOOKUP(G100,BD_GICS!C:D,2,0),"") | L100: =+IFERROR(VLOOKUP(H100,BD_GICS!E:F,2,0),"") | M100: =+IFERROR(VLOOKUP(I100,BD_GICS!G:H,2,0),"")
A101: Credit | B101: MCCDF | C101: RISERVA | D101: 4321986.5 | E101: 1411 | F101: 14 | G101: 1411 | H101: 1411 | I101: 1411 | J101: =+IFERROR(VLOOKUP(F101,BD_GICS!A:B,2,0),"") -> Financials | K101: =+IFERROR(VLOOKUP(G101,BD_GICS!C:D,2,0),"") -> Financial Services | L101: =+IFERROR(VLOOKUP(H101,BD_GICS!E:F,2,0),"") | M101: =+IFERROR(VLOOKUP(I101,BD_GICS!G:H,2,0),"")
A102: Credit | B102: MCCDF | C102: ROCKFORD TOWER CLO 2022-1 | D102: 2712314.4 | E102: CLO | J102: =+IFERROR(VLOOKUP(F102,BD_GICS!A:B,2,0),"") | K102: =+IFERROR(VLOOKUP(G102,BD_GICS!C:D,2,0),"") | L102: =+IFERROR(VLOOKUP(H102,BD_GICS!E:F,2,0),"") | M102: =+IFERROR(VLOOKUP(I102,BD_GICS!G:H,2,0),"")
A103: Credit | B103: MCCDF | C103: VOYA EURO CLO | D103: 1326093.9 | E103: CLO | J103: =+IFERROR(VLOOKUP(F103,BD_GICS!A:B,2,0),"") | K103: =+IFERROR(VLOOKUP(G103,BD_GICS!C:D,2,0),"") | L103: =+IFERROR(VLOOKUP(H103,BD_GICS!E:F,2,0),"") | M103: =+IFERROR(VLOOKUP(I103,BD_GICS!G:H,2,0),"")
A104: Credit | B104: MCCDF | C104: WIND RIVER CLO | D104: 4328922.2 | E104: CLO | J104: =+IFERROR(VLOOKUP(F104,BD_GICS!A:B,2,0),"") | K104: =+IFERROR(VLOOKUP(G104,BD_GICS!C:D,2,0),"") | L104: =+IFERROR(VLOOKUP(H104,BD_GICS!E:F,2,0),"") | M104: =+IFERROR(VLOOKUP(I104,BD_GICS!G:H,2,0),"")
A105: Credit | B105: MCPPP | C105: ABASTIBLE | D105: 158396.36 | E105: 20101110 | F105: 20 | G105: 2010 | H105: 201011 | I105: 20101110 | J105: =+IFERROR(VLOOKUP(F105,BD_GICS!A:B,2,0),"") -> Utilities | K105: =+IFERROR(VLOOKUP(G105,BD_GICS!C:D,2,0),"") -> Utilities | L105: =+IFERROR(VLOOKUP(H105,BD_GICS!E:F,2,0),"") -> Gas & Water Utilities | M105: =+IFERROR(VLOOKUP(I105,BD_GICS!G:H,2,0),"") -> Gas Utilities
A106: Credit | B106: MCPPP | C106: AD RETAIL | D106: 642590.93 | E106: 3231 | F106: 32 | G106: 3231 | H106: 3231 | I106: 3231 | J106: =+IFERROR(VLOOKUP(F106,BD_GICS!A:B,2,0),"") -> Consumer Discretionary | K106: =+IFERROR(VLOOKUP(G106,BD_GICS!C:D,2,0),"") -> Department Stores | L106: =+IFERROR(VLOOKUP(H106,BD_GICS!E:F,2,0),"") | M106: =+IFERROR(VLOOKUP(I106,BD_GICS!G:H,2,0),"")
A107: Credit | B107: MCPPP | C107: AGROSUPER | D107: 3708.1738 | E107: 1211101116 | F107: 12 | G107: 1211 | H107: 121110 | I107: 12111011 | J107: =+IFERROR(VLOOKUP(F107,BD_GICS!A:B,2,0),"") -> Consumer Staples | K107: =+IFERROR(VLOOKUP(G107,BD_GICS!C:D,2,0),"") -> Retail & Wholesale - Staples | L107: =+IFERROR(VLOOKUP(H107,BD_GICS!E:F,2,0),"") -> Wholesale - Consumer Staples | M107: =+IFERROR(VLOOKUP(I107,BD_GICS!G:H,2,0),"") -> Food & Beverage Wholesalers
A108: Credit | B108: MCPPP | C108: AGUAS ANDINAS | D108: 10235.398 | E108: 2010 | F108: 20 | G108: 2010 | H108: 2010 | I108: 2010 | J108: =+IFERROR(VLOOKUP(F108,BD_GICS!A:B,2,0),"") -> Utilities | K108: =+IFERROR(VLOOKUP(G108,BD_GICS!C:D,2,0),"") -> Utilities | L108: =+IFERROR(VLOOKUP(H108,BD_GICS!E:F,2,0),"") | M108: =+IFERROR(VLOOKUP(I108,BD_GICS!G:H,2,0),"")
A109: Credit | B109: MCPPP | C109: AGUAS ARAUCANIA | D109: 112574.25 | E109: 20101111 | F109: 20 | G109: 2010 | H109: 201011 | I109: 20101111 | J109: =+IFERROR(VLOOKUP(F109,BD_GICS!A:B,2,0),"") -> Utilities | K109: =+IFERROR(VLOOKUP(G109,BD_GICS!C:D,2,0),"") -> Utilities | L109: =+IFERROR(VLOOKUP(H109,BD_GICS!E:F,2,0),"") -> Gas & Water Utilities | M109: =+IFERROR(VLOOKUP(I109,BD_GICS!G:H,2,0),"") -> Water Utilities
A110: Credit | B110: MCPPP | C110: ANGLO AMERICAN | D110: 101860.13 | E110: 1810151211 | F110: 18 | G110: 1810 | H110: 181015 | I110: 18101512 | J110: =+IFERROR(VLOOKUP(F110,BD_GICS!A:B,2,0),"") -> Materials | K110: =+IFERROR(VLOOKUP(G110,BD_GICS!C:D,2,0),"") -> Materials | L110: =+IFERROR(VLOOKUP(H110,BD_GICS!E:F,2,0),"") -> Metals & Mining | M110: =+IFERROR(VLOOKUP(I110,BD_GICS!G:H,2,0),"") -> Precious Metals
A111: Credit | B111: MCPPP | C111: ANTOFAGASTA MINERALS | D111: 587447.78 | E111: 3011 | F111: 30 | G111: 3011 | H111: 3011 | I111: 3011 | J111: =+IFERROR(VLOOKUP(F111,BD_GICS!A:B,2,0),"") -> Materials | K111: =+IFERROR(VLOOKUP(G111,BD_GICS!C:D,2,0),"") -> Metals & Mining | L111: =+IFERROR(VLOOKUP(H111,BD_GICS!E:F,2,0),"") | M111: =+IFERROR(VLOOKUP(I111,BD_GICS!G:H,2,0),"")
A112: Credit | B112: MCPPP | C112: AQUACHILE | D112: 2616.2805 | E112: 1210101115 | F112: 12 | G112: 1210 | H112: 121010 | I112: 12101011 | J112: =+IFERROR(VLOOKUP(F112,BD_GICS!A:B,2,0),"") -> Consumer Staples | K112: =+IFERROR(VLOOKUP(G112,BD_GICS!C:D,2,0),"") -> Consumer Staple Products | L112: =+IFERROR(VLOOKUP(H112,BD_GICS!E:F,2,0),"") -> Food | M112: =+IFERROR(VLOOKUP(I112,BD_GICS!G:H,2,0),"") -> Packaged Food
A113: Credit | B113: MCPPP | C113: BANCO CHILE | D113: 20325.861 | E113: 1410101111 | F113: 14 | G113: 1410 | H113: 141010 | I113: 14101011 | J113: =+IFERROR(VLOOKUP(F113,BD_GICS!A:B,2,0),"") -> Financials | K113: =+IFERROR(VLOOKUP(G113,BD_GICS!C:D,2,0),"") -> Banking | L113: =+IFERROR(VLOOKUP(H113,BD_GICS!E:F,2,0),"") -> Banking | M113: =+IFERROR(VLOOKUP(I113,BD_GICS!G:H,2,0),"") -> Banks
...

Sheet BD_GICS
A1: SECTOR CODE | B1: SECTOR NAME | C1: INDUSTRY GROUP CODE | D1: INDUSTRY GROUP NAME | E1: INDUSTRY CODE | F1: INDUSTRY NAME | G1: SUB INDUSTRY CODE | H1: SUB INDUSTRY NAME
A2: 10 | B2: Communications | C2: 1010 | D2: Media | E2: 101010 | F2: Advertising & Marketing | G2: 10101010 | H2: Advertising & Marketing
A3: 10 | B3: Communications | C3: 1010 | D3: Media | E3: 101011 | F3: Cable & Satellite | G3: 10101110 | H3: Cable & Satellite
A4: 10 | B4: Communications | C4: 1010 | D4: Media | E4: 101012 | F4: Entertainment Content | G4: 10101210 | H4: Film & TV
A5: 10 | B5: Communications | C5: 1010 | D5: Media | E5: 101012 | F5: Entertainment Content | G5: 10101211 | H5: Music
A6: 10 | B6: Communications | C6: 1010 | D6: Media | E6: 101012 | F6: Entertainment Content | G6: 10101212 | H6: Video Games
A7: 10 | B7: Communications | C7: 1010 | D7: Media | E7: 101013 | F7: Publishing & Broadcasting | G7: 10101310 | H7: Publishing
A8: 10 | B8: Communications | C8: 1010 | D8: Media | E8: 101013 | F8: Publishing & Broadcasting | G8: 10101311 | H8: Local TV & Radio Broadcast
A9: 10 | B9: Communications | C9: 1010 | D9: Media | E9: 101013 | F9: Publishing & Broadcasting | G9: 10101312 | H9: Out-of-Home Display Advertising
A10: 10 | B10: Communications | C10: 1010 | D10: Media | E10: 101014 | F10: Internet Media & Services | G10: 10101410 | H10: Internet Media & Services
A11: 10 | B11: Communications | C11: 1011 | D11: Telecommunications | E11: 101110 | F11: Telecommunications | G11: 10111010 | H11: Wireless Telecommunications
A12: 10 | B12: Communications | C12: 1011 | D12: Telecommunications | E12: 101110 | F12: Telecommunications | G12: 10111011 | H12: Wireline Telecommunications
A13: 11 | B13: Consumer Discretionary | C13: 1110 | D13: Consumer Discretionary Products | E13: 111010 | F13: Apparel & Textile Products | G13: 11101010 | H13: Apparel, Footwear & Acc Design
... A215: 20 | B215: Utilities | C215: 2010 | D215: Utilities | E215: 201012 | F215: Elec & Gas Marketing & Trading | G215: 20101210 | H215: Elec & Gas Marketing & Trading
A216: 30 | B216: Materials | C216: 3010 | D216: Forest & Paper Products Manufacturing
A217: 30 | B217: Materials | C217: 3011 | D217: Metals & Mining
A218: 30 | B218: Materials | C218: 3012 | D218: Construction Materials Manufacturing
A219: 30 | B219: Materials | C219: 3013 | D219: Chemicals
A220: 30 | B220: Materials | C220: 3014 | D220: Containers & Packaging
A221: 31 | B221: Communications | C221: 3110 | D221: Cable & Satellite
A222: 31 | B222: Communications | C222: 3111 | D222: Wireline Telecommunications Services
A223: 31 | B223: Communications | C223: 3112 | D223: Internet Media
A224: 31 | B224: Communications | C224: 3113 | D224: Wireless Telecommunications Services
A225: 31 | B225: Communications | C225: 3114 | D225: Entertainment Content
A226: 31 | B226: Communications | C226: 3115 | D226: Publishing & Broadcasting
A227: 31 | B227: Communications | C227: 3116 | D227: Advertising & Marketing
... A294: 50 | B294: Government | C294: 5017 | D294: Government Local
